Workbook

Sheet Pricing 1
A2: Pricing Targets
A3: Metric | B3: Target
A4: Total Target Price | B4: ≈ | C4: 45000000
A5: Y1 Target Price | B5: ≤ | C5: 11000000
A6: GP%
A7: Managed Services | B7: ≥ | C7: 0.25
A8: Consult | B8: ≥ | C8: 0.3
A9: Third Party SW | B9: ≥ | C9: 0.2
A10: *Third Party SW revenues recognized over 60 months
A12: Cost
A13: Solution elements | D13: Service Tower | E13: Y1 | F13: Y2 | G13: Y3 | H13: Y4 | I13: Y5 | J13: Total
A14: Discovery Phase | D14: =A8 -> Consult | E14: 300000 | F14: 0 | G14: 0 | H14: 0 | I14: 0 | J14: =SUM(E14:I14) -> 300000
A15: Migration and Application Modernization | D15: =A8 -> Consult | E15: 2800000 | F15: =E15 -> 2800000 | G15: =F15/12*9 -> 2100000 | H15: 0 | I15: 0 | J15: =SUM(E15:I15) -> 7700000
A16: Advanced SW License for 6 years | D16: =A9 -> Third Party SW | E16: 6850000 | F16: 0 | G16: 0 | H16: 0 | I16: 0 | J16: =SUM(E16:I16) -> 6850000
A17: Microfocus SW Licenses for 6 years | D17: =A9 -> Third Party SW | E17: 5300000 | F17: 0 | G17: 0 | H17: 0 | I17: 0 | J17: =SUM(E17:I17) -> 5300000
A18: Network Services | D18: =A7 -> Managed Services | E18: 780000 | F18: =E18 -> 780000 | G18: =F18 -> 780000 | H18: =G18 -> 780000 | I18: =H18 -> 780000 | J18: =SUM(E18:I18) -> 3900000
A19: Managed Infrastructure Services | D19: =A7 -> Managed Services | E19: 1800000 | F19: =E19 -> 1800000 | G19: =F19 -> 1800000 | H19: =G19 -> 1800000 | I19: =H19 -> 1800000 | J19: =SUM(E19:I19) -> 9000000
A20: TOTAL | E20: =SUM(E14:E19) -> 17830000 | F20: =SUM(F14:F19) -> 5380000 | G20: =SUM(G14:G19) -> 4680000 | H20: =SUM(H14:H19) -> 2580000 | I20: =SUM(I14:I19) -> 2580000 | J20: =SUM(E20:I20) -> 33050000
A22: Price
A23: Solution elements | D23: Service Tower | E23: =E13 -> Y1 | F23: =F13 -> Y2 | G23: =G13 -> Y3 | H23: =H13 -> Y4 | I23: =I13 -> Y5 | J23: =J13 -> Total | K23: GP%
A24: =A14 -> Discovery Phase | D24: =D14 -> Consult | E24: =E14/(1-$K24) -> 428571.43 | F24: =F14/(1-$K24) -> 0 | G24: =G14/(1-$K24) -> 0 | H24: =H14/(1-$K24) -> 0 | I24: =I14/(1-$K24) -> 0 | J24: =SUM(E24:I24) -> 428571.43 | K24: =_xlfn.XLOOKUP(D24,$A$7:$A$9,$C$7:$C$9) -> 0.3
A25: =A15 -> Migration and Application Modernization | D25: =D15 -> Consult | E25: =E15/(1-$K25) -> 4000000 | F25: =F15/(1-$K25) -> 4000000 | G25: =G15/(1-$K25) -> 3000000 | H25: =H15/(1-$K25) -> 0 | I25: =I15/(1-$K25) -> 0 | J25: =SUM(E25:I25) -> 11000000 | K25: =_xlfn.XLOOKUP(D25,$A$7:$A$9,$C$7:$C$9) -> 0.3
A26: =A16 -> Advanced SW License for 6 years | D26: =D16 -> Third Party SW | E26: =E16/(1-$K26) -> 8562500 | F26: =F16/(1-$K26) -> 0 | G26: =G16/(1-$K26) -> 0 | H26: =H16/(1-$K26) -> 0 | I26: =I16/(1-$K26) -> 0 | J26: =SUM(E26:I26) -> 8562500 | K26: =_xlfn.XLOOKUP(D26,$A$7:$A$9,$C$7:$C$9) -> 0.2
A27: =A17 -> Microfocus SW Licenses for 6 years | D27: =D17 -> Third Party SW | E27: =E17/(1-$K27) -> 6625000 | F27: =F17/(1-$K27) -> 0 | G27: =G17/(1-$K27) -> 0 | H27: =H17/(1-$K27) -> 0 | I27: =I17/(1-$K27) -> 0 | J27: =SUM(E27:I27) -> 6625000 | K27: =_xlfn.XLOOKUP(D27,$A$7:$A$9,$C$7:$C$9) -> 0.2
A28: =A18 -> Network Services | D28: =D18 -> Managed Services | E28: =E18/(1-$K28) -> 1040000 | F28: =F18/(1-$K28) -> 1040000 | G28: =G18/(1-$K28) -> 1040000 | H28: =H18/(1-$K28) -> 1040000 | I28: =I18/(1-$K28) -> 1040000 | J28: =SUM(E28:I28) -> 5200000 | K28: =_xlfn.XLOOKUP(D28,$A$7:$A$9,$C$7:$C$9) -> 0.25
A29: =A19 -> Managed Infrastructure Services | D29: =D19 -> Managed Services | E29: =E19/(1-$K29) -> 2400000 | F29: =F19/(1-$K29) -> 2400000 | G29: =G19/(1-$K29) -> 2400000 | H29: =H19/(1-$K29) -> 2400000 | I29: =I19/(1-$K29) -> 2400000 | J29: =SUM(E29:I29) -> 12000000 | K29: =_xlfn.XLOOKUP(D29,$A$7:$A$9,$C$7:$C$9) -> 0.25
A30: TOTAL | E30: =SUM(E24:E29) -> 23056071 | F30: =SUM(F24:F29) -> 7440000 | G30: =SUM(G24:G29) -> 6440000 | H30: =SUM(H24:H29) -> 3440000 | I30: =SUM(I24:I29) -> 3440000 | J30: =SUM(E30:I30) -> 43816071
D32: Price (Client View)
D33: Service Tower | E33: =E23 -> Y1 | F33: =F23 -> Y2 | G33: =G23 -> Y3 | H33: =H23 -> Y4 | I33: =I23 -> Y5 | J33: =J23 -> Total | K33: GP%
D34: =D24 -> Consult | E34: =E58 -> 4531506.4 | F34: =F58 -> 4102934.9 | G34: =G58 -> 3102934.9 | H34: =H58 -> 0 | I34: =I58 -> 0 | J34: =SUM(E34:I34) -> 11737376 | K34: =(J34-SUMIF($D$14:$D$19,D34,$J$14:$J$19))/J34 -> 0.31841667
D35: =D26 -> Third Party SW | E35: =E59+E63 -> 2935543.4 | F35: =F59-E63 -> 4367403.9 | G35: =G59 -> 3431532 | H35: =H59 -> 3431532 | I35: =I59 -> 1431861.3 | J35: =SUM(E35:I35) -> 15597873 | K35: =(J35-SUMIF($D$14:$D$19,D35,$J$14:$J$19))/J35 -> 0.22104762
D36: =D28 -> Managed Services | E36: =E60 -> 3532950.2 | F36: =F60 -> 3532950.2 | G36: =G60 -> 3532950.2 | H36: =H60 -> 3532950.2 | I36: =I60 -> 3532950.2 | J36: =SUM(E36:I36) -> 17664751 | K36: =(J36-SUMIF($D$14:$D$19,D36,$J$14:$J$19))/J36 -> 0.26973214
D38: TOTAL | E38: =SUM(E34:E37) -> 11000000 | F38: =SUM(F34:F37) -> 12003289 | G38: =SUM(G34:G37) -> 10067417 | H38: =SUM(H34:H37) -> 6964482.2 | I38: =SUM(I34:I37) -> 4964811.5 | J38: =SUM(E38:I38) -> 45000000
C42: PRICE ADJUSTMENT
D46: Base Price - Before Markup
D47: Service Tower | E47: =E33 -> Y1 | F47: =F33 -> Y2 | G47: =G33 -> Y3 | H47: =H33 -> Y4 | I47: =I33 -> Y5 | J47: =J23 -> Total | K47: Markup per service tower | L47: Markup per year | M47: Total+Markup
D48: =$D$24 -> Consult | E48: =SUMIF($D$24:$D$29,$D48,E$24:E$29) -> 4428571.4 | F48: =SUMIF($D$24:$D$29,$D48,F$24:F$29) -> 4000000 | G48: =SUMIF($D$24:$D$29,$D48,G$24:G$29) -> 3000000 | H48: =SUMIF($D$24:$D$29,$D48,H$24:H$29) -> 0 | I48: =SUMIF($D$24:$D$29,$D48,I$24:I$29) -> 0 | J48: =SUM(E48:I48) -> 11428571 | K48: =J48/$J$52*$K$52 -> 308804.78 | L48: =K48/COUNTIF($E48:$I48,"<>0") -> 102934.93 | M48: =J48+K48 -> 11737376
D49: =$D$26 -> Third Party SW | E49: =SUMIF($D$24:$D$29,$D49,E$24:E$29) -> 15187500 | F49: =SUMIF($D$24:$D$29,$D49,F$24:F$29) -> 0 | G49: =SUMIF($D$24:$D$29,$D49,G$24:G$29) -> 0 | H49: =SUMIF($D$24:$D$29,$D49,H$24:H$29) -> 0 | I49: =SUMIF($D$24:$D$29,$D49,I$24:I$29) -> 0 | J49: =SUM(E49:I49) -> 15187500 | K49: =J49/$J$52*$K$52 -> 410372.6 | L49: =K49/COUNTIF($E49:$I49,"<>0") -> 410372.6 | M49: =J49+K49 -> 15597873
D50: =$D$28 -> Managed Services | E50: =SUMIF($D$24:$D$29,$D50,E$24:E$29) -> 3440000 | F50: =SUMIF($D$24:$D$29,$D50,F$24:F$29) -> 3440000 | G50: =SUMIF($D$24:$D$29,$D50,G$24:G$29) -> 3440000 | H50: =SUMIF($D$24:$D$29,$D50,H$24:H$29) -> 3440000 | I50: =SUMIF($D$24:$D$29,$D50,I$24:I$29) -> 3440000 | J50: =SUM(E50:I50) -> 17200000 | K50: =J50/$J$52*$K$52 -> 464751.19 | L50: =K50/COUNTIF($E50:$I50,"<>0") -> 92950.238 | M50: =J50+K50 -> 17664751
D52: TOTAL | E52: =SUM(E48:E51) -> 23056071 | F52: =SUM(F48:F51) -> 7440000 | G52: =SUM(G48:G51) -> 6440000 | H52: =SUM(H48:H51) -> 3440000 | I52: =SUM(I48:I51) -> 3440000 | J52: =SUM(E52:I52) -> 43816071 | K52: =C4-J52 -> 1183928.6
...

Sheet Financials 2
B3: Financial Targets
B4: Metric | C4: Target
B5: Total PTI | C5: ≥ | D5: 0.1
B6: Y1 PTI | C6: ≥ | D6: 0.1
B7: IRR | C7: ≥ | D7: 0.2
B8: Expenses | C8: = | D8: 0.15
B9: Corporate Tax | C9: = | D9: 0.2
B11: I&E Statement
D12: Y1(12) | E12: Y2(12) | F12: Y3(12) | G12: Y4(12) | H12: Y5(12) | I12: ='Pricing 1'!J47 -> Total
B13: Revenue | D13: ='Pricing 1'!E34+'Pricing 1'!$J$35/5+'Pricing 1'!E36 -> 11184031 | E13: ='Pricing 1'!F34+'Pricing 1'!$J$35/5+'Pricing 1'!F36 -> 10755460 | F13: ='Pricing 1'!G34+'Pricing 1'!$J$35/5+'Pricing 1'!G36 -> 9755459.7 | G13: ='Pricing 1'!H34+'Pricing 1'!$J$35/5+'Pricing 1'!H36 -> 6652524.8 | H13: ='Pricing 1'!I34+'Pricing 1'!$J$35/5+'Pricing 1'!I36 -> 6652524.8 | I13: =SUM(D13:H13) -> 45000000
B14: Cost | D14: ='Pricing 1'!E14+'Pricing 1'!E15+('Pricing 1'!$J$16+'Pricing 1'!$J$17)/5+'Pricing 1'!E18+'Pricing 1'!E19 -> 8110000 | E14: ='Pricing 1'!F14+'Pricing 1'!F15+('Pricing 1'!$J$16+'Pricing 1'!$J$17)/5+'Pricing 1'!F18+'Pricing 1'!F19 -> 7810000 | F14: ='Pricing 1'!G14+'Pricing 1'!G15+('Pricing 1'!$J$16+'Pricing 1'!$J$17)/5+'Pricing 1'!G18+'Pricing 1'!G19 -> 7110000 | G14: ='Pricing 1'!H14+'Pricing 1'!H15+('Pricing 1'!$J$16+'Pricing 1'!$J$17)/5+'Pricing 1'!H18+'Pricing 1'!H19 -> 5010000 | H14: ='Pricing 1'!I14+'Pricing 1'!I15+('Pricing 1'!$J$16+'Pricing 1'!$J$17)/5+'Pricing 1'!I18+'Pricing 1'!I19 -> 5010000 | I14: =SUM(D14:H14) -> 33050000
B15: Gross Profit (GP) | D15: =D13-D14 -> 3074031.1 | E15: =E13-E14 -> 2945459.7 | F15: =F13-F14 -> 2645459.7 | G15: =G13-G14 -> 1642524.8 | H15: =H13-H14 -> 1642524.8 | I15: =SUM(D15:H15) -> 11950000
B16: GP% | D16: =D15/D13 -> 0.27485896 | E16: =E15/E13 -> 0.27385716 | F16: =F15/F13 -> 0.27117735 | G16: =G15/G13 -> 0.24690246 | H16: =H15/H13 -> 0.24690246 | I16: =I15/I13 -> 0.26555556
B17: Expenses | D17: =D13*$D$8 -> 1677604.7 | E17: =E13*$D$8 -> 1613319 | F17: =F13*$D$8 -> 1463319 | G17: =G13*$D$8 -> 997878.71 | H17: =H13*$D$8 -> 997878.71 | I17: =SUM(D17:H17) -> 6750000
B18: Pre Tax Income (PTI) | D18: =D15-D17 -> 1396426.4 | E18: =E15-E17 -> 1332140.7 | F18: =F15-F17 -> 1182140.7 | G18: =G15-G17 -> 644646.04 | H18: =H15-H17 -> 644646.04 | I18: =SUM(D18:H18) -> 5200000
B19: PTI% | D19: =D18/D13 -> 0.12485896 | E19: =E18/E13 -> 0.12385716 | F19: =F18/F13 -> 0.12117735 | G19: =G18/G13 -> 0.096902465 | H19: =H18/H13 -> 0.096902465 | I19: =I18/I13 -> 0.11555556
B20: Corporate Tax | D20: =D18*$D$9 -> 279285.29 | E20: =E18*$D$9 -> 266428.15 | F20: =F18*$D$9 -> 236428.15 | G20: =G18*$D$9 -> 128929.21 | H20: =H18*$D$9 -> 128929.21 | I20: =SUM(D20:H20) -> 1040000
B21: Net Income | D21: =D18-D20 -> 1117141.2 | E21: =E18-E20 -> 1065712.6 | F21: =F18-F20 -> 945712.59 | G21: =G18-G20 -> 515716.84 | H21: =H18-H20 -> 515716.84 | I21: =SUM(D21:H21) -> 4160000
B23: Cash Flow Statement
D24: Y1(12) | E24: Y2(12) | F24: Y3(12) | G24: Y4(12) | H24: Y5(12) | I24: Total (48)
B25: Cash inflow during the period | D25: ='Pricing 1'!E38 -> 11000000 | E25: ='Pricing 1'!F38 -> 12003289 | F25: ='Pricing 1'!G38 -> 10067417 | G25: ='Pricing 1'!H38 -> 6964482.2 | H25: ='Pricing 1'!I38 -> 4964811.5 | I25: =SUM(D25:H25) -> 45000000
B26: Cash outflow during the period | D26: ='Pricing 1'!E20+D17+D20 -> 19786890 | E26: ='Pricing 1'!F20+E17+E20 -> 7259747.1 | F26: ='Pricing 1'!G20+F17+F20 -> 6379747.1 | G26: ='Pricing 1'!H20+G17+G20 -> 3706807.9 | H26: ='Pricing 1'!I20+H17+H20 -> 3706807.9 | I26: =SUM(D26:H26) -> 40840000
B27: Net Cash | D27: =D25-D26 -> -8786890 | E27: =E25-E26 -> 4743542 | F27: =F25-F26 -> 3687670 | G27: =G25-G26 -> 3257674.3 | H27: =H25-H26 -> 1258003.6 | I27: =SUM(D27:H27) -> 4160000
B28: IRR | D28: =IRR(D27:H27) -> 0.21564468
B30: NPV Calculation
B31: NPV | D31: =NPV(D32,D27:H27) -> 1042209.1
B32: WACC | D32: =D39*D33+(D37*D40)*(1-D9) -> 0.1381902
B33: Cost of equity | D33: =D34+D35*(D36-D34) -> 0.275972
B34: Risk Free Rate (U.S. 3-Month T-Bill) | D34: 0.0358
B35: Kyndryl Beta (5Y Monthly) | D35: 1.94
B36: Market Rate (S&P 500 Average annualized return) | D36: 0.1596
B37: Cost of Debt | D37: 0.08
B38: Kyndryl Capital Structure | D38: =SUM(D39:D40) -> 1
B39: Equity | D39: 0.35
B40: Debt | D40: =1-D39 -> 0.65
